Workbook

Sheet Sales Statement
B4: Serial | C4: Month | D4: 46113 | G4: 46143 | J4: 46174 | M4: 46204 | P4: 46235
C5: Party Name | D5: Total Price | E5: Paid Amount | F5: Dues Amount | G5: Total Price | H5: Paid Amount | I5: Dues Amount | J5: Total Price | K5: Paid Amount | L5: Dues Amount | M5: Total Price | N5: Paid Amount | O5: Dues Amount | P5: Total Price | Q5: Paid Amount | R5: Dues Amount
B6: 1 | C6: Ark Hospital | D6: ='ARK Hospital'!G8 -> 60700 | E6: ='ARK Hospital'!H8 -> 60700 | F6: =IF(AND(D6="", E6=""), "", D6-E6) -> 0 | G6: ='ARK Hospital'!G18 -> 163500 | H6: ='ARK Hospital'!H18 -> 163500 | I6: =IF(AND(G6="",H6=""),"",G6-H6) -> 0 | J6: ='ARK Hospital'!G25 -> 142800 | K6: ='ARK Hospital'!H25 -> 142800 | L6: =IF(AND(J6="", K6=""), "", J6-K6) -> 0 | O6: =IF(AND(M6="",N6=""), "", M6-N6) | R6: =IF(AND(P6="",Q6=""),"", P6-Q6)
B7: 2 | C7: Bismillah Surgical | D7: ='Bismillah Surgical'!G13 -> 121200 | E7: ='Bismillah Surgical'!H13 -> 121200 | F7: =IF(AND(D7="", E7=""), "", D7-E7) -> 0 | G7: 0 | H7: 0 | I7: =IF(AND(G7="",H7=""),"",G7-H7) -> 0 | L7: =IF(AND(J7="", K7=""), "", J7-K7) | R7: =IF(AND(P7="",Q7=""),"", P7-Q7)
B8: 3 | C8: Popular Medicine AND Departmental Store | D8: ='Popular Medcine & Departmental '!G9 -> 30987 | E8: ='Popular Medcine & Departmental '!H9 -> 30987 | F8: =IF(AND(D8="", E8=""), "", D8-E8) -> 0 | I8: =IF(AND(G8="",H8=""),"",G8-H8) | J8: ='Popular Medcine & Departmental '!G15 -> 28050 | K8: ='Popular Medcine & Departmental '!H15 -> 28050 | L8: =IF(AND(J8="", K8=""), "", J8-K8) -> 0 | O8: =IF(AND(M8="",N8=""), "", M8-N8) | P8: ='Popular Medcine & Departmental '!G21 -> 27900 | Q8: 0 | R8: =IF(AND(P8="",Q8=""),"", P8-Q8) -> 27900
B9: 4 | C9: Kuwait Moitri Hospital | D9: ='Kuwait Moitri Hospital'!H9 -> 27600 | E9: ='Kuwait Moitri Hospital'!I9 -> 27600 | F9: =IF(AND(D9="", E9=""), "", D9-E9) -> 0 | G9: 0 | I9: 0 | L9: =IF(AND(J9="", K9=""), "", J9-K9) | O9: =IF(AND(M9="",N9=""), "", M9-N9) | R9: =IF(AND(P9="",Q9=""),"", P9-Q9)
B10: 5 | C10: VIP PHARMA-HAZI PHARMA | D10: ='VIP PHARMA-HAZI PHARMA'!H8 -> 97800 | E10: ='VIP PHARMA-HAZI PHARMA'!I8 -> 97800 | F10: =IF(AND(D10="", E10=""), "", D10-E10) -> 0 | L10: =IF(AND(J10="", K10=""), "", J10-K10) | O10: =IF(AND(M10="",N10=""), "", M10-N10) | R10: =IF(AND(P10="",Q10=""),"", P10-Q10)
B11: 6 | C11: Mr. Afjal | F11: =IF(AND(D11="", E11=""), "", D11-E11) | G11: ='Mr. Afjal'!H9 -> 20700 | H11: ='Mr. Afjal'!I9 -> 20700 | I11: =IF(AND(G11="",H11=""),"",G11-H11) -> 0 | L11: =IF(AND(J11="", K11=""), "", J11-K11) | R11: =IF(AND(P11="",Q11=""),"", P11-Q11) | S11: Column1
B12: 7 | C12: AR Medi Corporation | F12: =IF(AND(D12="", E12=""), "", D12-E12) | G12: ='AR Medi Corporation'!G9 -> 29750 | H12: ='AR Medi Corporation'!H9 -> 29750 | I12: =IF(AND(G12="",H12=""),"",G12-H12) -> 0 | L12: =IF(AND(J12="", K12=""), "", J12-K12) | O12: =IF(AND(M12="",N12=""), "", M12-N12) | P12: 52000 | Q12: 52000
B13: 8 | C13: SG Pharma Shamoly | F13: =IF(AND(D13="", E13=""), "", D13-E13) | G13: ='SG Pharma Shamoly'!G7 -> 20700 | H13: ='SG Pharma Shamoly'!H7 -> 20700 | I13: =IF(AND(G13="",H13=""),"",G13-H13) -> 0 | L13: =IF(AND(J13="", K13=""), "", J13-K13) | O13: =IF(AND(M13="",N13=""), "", M13-N13) | R13: =IF(AND(P13="",Q13=""),"", P13-Q13)
B14: 9 | C14: Anima Medical | F14: =IF(AND(D14="", E14=""), "", D14-E14) | G14: ='Onima Medical'!H9 -> 6600 | H14: ='Onima Medical'!I9 -> 6600 | I14: =IF(AND(G14="",H14=""),"",G14-H14) -> 0 | L14: =IF(AND(J14="", K14=""), "", J14-K14) | O14: =IF(AND(M14="",N14=""), "", M14-N14) | R14: =IF(AND(P14="",Q14=""),"", P14-Q14)
B15: 10 | C15: Rahman Pharma | F15: =IF(AND(D15="", E15=""), "", D15-E15) | G15: ='Rahman Pharma'!I7 -> 20850 | H15: ='Rahman Pharma'!J7 -> 20850 | I15: =IF(AND(G15="",H15=""),"",G15-H15) -> 0 | L15: =IF(AND(J15="", K15=""), "", J15-K15) | O15: =IF(AND(M15="",N15=""), "", M15-N15) | R15: =IF(AND(P15="",Q15=""),"", P15-Q15)
B16: 11 | C16: Norshingdi Pharma | D16: ='Norshingdi Pharma'!G7 -> 20400 | E16: ='Norshingdi Pharma'!H7 -> 20400 | F16: =IF(AND(D16="", E16=""), "", D16-E16) -> 0 | I16: =IF(AND(G16="",H16=""),"",G16-H16) | J16: ='Norshingdi Pharma'!G11 -> 20400 | K16: ='Norshingdi Pharma'!H11 -> 20400 | L16: =IF(AND(J16="", K16=""), "", J16-K16) -> 0 | M16: ='Norshingdi Pharma'!G16 -> 27300 | N16: ='Norshingdi Pharma'!H16 -> 27300 | O16: =IF(AND(M16="",N16=""), "", M16-N16) -> 0 | R16: =IF(AND(P16="",Q16=""),"", P16-Q16)
B17: 12 | C17: MA Pharmacy Medical | F17: =IF(AND(D17="", E17=""), "", D17-E17) | G17: ='MA Pharmacy'!I7 -> 97500 | H17: ='MA Pharmacy'!J7 -> 97500 | I17: =IF(AND(G17="",H17=""),"",G17-H17) -> 0 | L17: =IF(AND(J17="", K17=""), "", J17-K17) | O17: =IF(AND(M17="",N17=""), "", M17-N17) | R17: =IF(AND(P17="",Q17=""),"", P17-Q17)
B18: 13 | C18: Life Surgical | F18: =IF(AND(D18="", E18=""), "", D18-E18) | G18: ='Life Surgical'!G8 -> 20900 | H18: ='Life Surgical'!H8 -> 20900 | I18: =IF(AND(G18="",H18=""),"",G18-H18) -> 0 | J18: ='Life Surgical'!G12 -> 20400 | K18: ='Life Surgical'!H12 -> 20400 | L18: =IF(AND(J18="", K18=""), "", J18-K18) -> 0 | O18: =IF(AND(M18="",N18=""), "", M18-N18) | R18: =IF(AND(P18="",Q18=""),"", P18-Q18)
B19: 14 | C19: Chittagong Healthcare | F19: =IF(AND(D19="", E19=""), "", D19-E19) | G19: ='Chittagong Healthcare'!G14 -> 453700 | H19: ='Chittagong Healthcare'!H14 -> 453700 | I19: =IF(AND(G19="",H19=""),"",G19-H19) -> 0 | L19: =IF(AND(J19="", K19=""), "", J19-K19) | O19: =IF(AND(M19="",N19=""), "", M19-N19) | R19: =IF(AND(P19="",Q19=""),"", P19-Q19)
B20: 15 | C20: Happy Life Pharmacy | F20: =IF(AND(D20="", E20=""), "", D20-E20) | I20: =IF(AND(G20="",H20=""),"",G20-H20) | J20: ='Happy Life Pharmacy'!H16 -> 27900 | K20: ='Happy Life Pharmacy'!I16 -> 27900 | L20: =IF(AND(J20="", K20=""), "", J20-K20) -> 0 | O20: =IF(AND(M20="",N20=""), "", M20-N20) | R20: =IF(AND(P20="",Q20=""),"", P20-Q20)
B21: 16 | C21: Royal Medical | F21: =IF(AND(D21="", E21=""), "", D21-E21) | I21: =IF(AND(G21="",H21=""),"",G21-H21) | J21: ='Royal Medical'!G6 -> 20400 | K21: ='Royal Medical'!H6 -> 20400 | L21: =IF(AND(J21="", K21=""), "", J21-K21) -> 0 | O21: =IF(AND(M21="",N21=""), "", M21-N21) | R21: =IF(AND(P21="",Q21=""),"", P21-Q21)
B22: 17 | C22: USB Hospital Uttara | F22: =IF(AND(D22="", E22=""), "", D22-E22) | I22: =IF(AND(G22="",H22=""),"",G22-H22) | J22: ='USB Hospital Uttara'!H7 -> 12000 | K22: ='USB Hospital Uttara'!I7 -> 12000 | L22: =IF(AND(J22="", K22=""), "", J22-K22) -> 0 | O22: =IF(AND(M22="",N22=""), "", M22-N22) | R22: =IF(AND(P22="",Q22=""),"", P22-Q22)
B23: 18 | C23: Asha International | F23: =IF(AND(D23="", E23=""), "", D23-E23) | I23: =IF(AND(G23="",H23=""),"",G23-H23) | J23: ='Asha International'!H7 -> 495000 | K23: ='Asha International'!I7 -> 400000 | L23: =IF(AND(J23="", K23=""), "", J23-K23) -> 95000 | O23: =IF(AND(M23="",N23=""), "", M23-N23) | R23: =IF(AND(P23="",Q23=""),"", P23-Q23)
B24: 19 | C24: Star Surgical | F24: =IF(AND(D24="", E24=""), "", D24-E24) | I24: =IF(AND(G24="",H24=""),"",G24-H24) | L24: =IF(AND(J24="", K24=""), "", J24-K24) | M24: ='Star Surgical'!H9 -> 68400 | N24: ='Star Surgical'!I9 -> 45400 | O24: =IF(AND(M24="",N24=""), "", M24-N24) -> 23000 | R24: =IF(AND(P24="",Q24=""),"", P24-Q24)
B25: 20 | C25: Sylhet Pharma | F25: =IF(AND(D25="", E25=""), "", D25-E25) | I25: =IF(AND(G25="",H25=""),"",G25-H25) | L25: =IF(AND(J25="", K25=""), "", J25-K25) | M25: ='Sylhet Pharma'!H8 -> 17820 | N25: ='Sylhet Pharma'!I8 -> 0 | O25: =IF(AND(M25="",N25=""), "", M25-N25) -> 17820 | R25: =IF(AND(P25="",Q25=""),"", P25-Q25)
B26: 21 | C26: Bulbul Surgical | F26: =IF(AND(D26="", E26=""), "", D26-E26) | I26: =IF(AND(G26="",H26=""),"",G26-H26) | L26: =IF(AND(J26="", K26=""), "", J26-K26) | M26: ='Bulbul Surgical'!I7 -> 0 | N26: ='Bulbul Surgical'!J7 -> 0 | O26: =IF(AND(M26="",N26=""), "", M26-N26) -> 0 | R26: =IF(AND(P26="",Q26=""),"", P26-Q26)
B27: 22 | C27: Suzon Pharma (Rangpur) | F27: =IF(AND(D27="", E27=""), "", D27-E27) | I27: =IF(AND(G27="",H27=""),"",G27-H27) | L27: =IF(AND(J27="", K27=""), "", J27-K27) | M27: ='Suzon Pharma (Rang)'!I10 -> 42000 | N27: ='Suzon Pharma (Rang)'!J10 -> 42000 | O27: =IF(AND(M27="",N27=""), "", M27-N27) -> 0 | R27: =IF(AND(P27="",Q27=""),"", P27-Q27)
B28: 23 | C28: SH Pharma | I28: =IF(AND(G28="",H28=""),"",G28-H28) | L28: =IF(AND(J28="", K28=""), "", J28-K28) | M28: ='SH Pharma'!H8 -> 93000 | N28: ='SH Pharma'!I8 -> 60000 | O28: =IF(AND(M28="",N28=""), "", M28-N28) -> 33000 | R28: =IF(AND(P28="",Q28=""),"", P28-Q28)
B29: 24 | C29: Mymen. Sayem Diagnostic Center | F29: =IF(AND(D29="", E29=""), "", D29-E29) | I29: =IF(AND(G29="",H29=""),"",G29-H29) | L29: =IF(AND(J29="", K29=""), "", J29-K29) | M29: ='Mymen. Sayem Diagnostic Center'!H7 -> 15000 | N29: ='Mymen. Sayem Diagnostic Center'!I7 -> 15000 | O29: =IF(AND(M29="",N29=""), "", M29-N29) -> 0 | R29: =IF(AND(P29="",Q29=""),"", P29-Q29)
B30: 25 | C30: Mitfort Hospital | F30: =IF(AND(D30="", E30=""), "", D30-E30) | I30: =IF(AND(G30="",H30=""),"",G30-H30) | J30: ='Mitfort Hospital'!K17 -> 1764520 | K30: ='Mitfort Hospital'!M17 -> 500000 | L30: =IF(AND(J30="", K30=""), "", J30-K30) -> 1264520 | O30: =IF(AND(M30="",N30=""), "", M30-N30) | R30: =IF(AND(P30="",Q30=""),"", P30-Q30)
B31: 26 | C31: Sonu Pharma
B32: 27 | C32: Insaf Baraka
C35: Total | D35: =SUM(D6:D30) -> 358687 | E35: =SUM(E6:E30) -> 358687 | F35: =SUM(F6:F30) -> 0 | G35: =SUM(G6:G30) -> 834200 | H35: =SUM(H6:H30) -> 834200 | I35: =SUM(I6:I30) -> 0 | J35: =SUM(J6:J30) -> 2531470 | K35: =SUM(K6:K30) -> 1171950 | ... P35: =SUM(P6:P30) -> 79900 | Q35: =SUM(Q6:Q34) -> 52000 | R35: =SUM(R6:R30) -> 27900

Sheet Products Delivery
C2: Products Delivery Statement-2026
C4: Item | D4: 46113 | F4: 46143 | H4: 46174 | J4: 46204 | L4: 46235
B5: Code | D5: Qty | E5: Unit Price | F5: Qty | G5: Unit Price | H5: Qty | I5: Unit Price | J5: Qty | K5: Unit Price | L5: Qty | M5: Unit Price
B6: ITEM01 | C6: Dialyzer 1.7H | D6: =IF(SUMIFS(Data!$D$2:$D$71,Data!$F$2:$F$71,$B6,Data!$B$2:$B$71,TEXT(D4,"mmmm"))=0,"",SUMIFS(Data!$D$2:$D$71,Data!$F$2:$F$71,$B6,Data!$B$2:$B$71,TEXT(D4,"mmmm"))) -> 120 | E6: =IFERROR(ROUND(AVERAGEIFS(Data!$E$2:$E$71,Data!$F$2:$F$71,$B6,Data!$B$2:$B$71,TEXT(D4,"mmmm")),2),"") -> 690 | F6: =IF(SUMIFS(Data!$D$2:$D$71,Data!$F$2:$F$71,$B6,Data!$B$2:$B$71,TEXT(F4,"mmmm"))=0,"",SUMIFS(Data!$D$2:$D$71,Data!$F$2:$F$71,$B6,Data!$B$2:$B$71,TEXT(F4,"mmmm"))) -> 330 | G6: =IFERROR(ROUND(AVERAGEIFS(Data!$E$2:$E$71,Data!$F$2:$F$71,$B6,Data!$B$2:$B$71,TEXT(F4,"mmmm")),2),"") -> 685 | H6: =IF(SUMIFS(Data!$D$2:$D$71,Data!$F$2:$F$71,$B6,Data!$B$2:$B$71,TEXT(H4,"mmmm"))=0,"",SUMIFS(Data!$D$2:$D$71,Data!$F$2:$F$71,$B6,Data!$B$2:$B$71,TEXT(H4,"mmmm"))) -> 1136 | I6: =IFERROR(ROUND(AVERAGEIFS(Data!$E$2:$E$71,Data!$F$2:$F$71,$B6,Data!$B$2:$B$71,TEXT(H4,"mmmm")),2),"") -> 352160 | J6: =IF(SUMIFS(Data!$D$2:$D$71,Data!$F$2:$F$71,$B6,Data!$B$2:$B$71,TEXT(J4,"mmmm"))=0,"",SUMIFS(Data!$D$2:$D$71,Data!$F$2:$F$71,$B6,Data!$B$2:$B$71,TEXT(J4,"mmmm"))) | K6: =IFERROR(ROUND(AVERAGEIFS(Data!$E$2:$E$71,Data!$F$2:$F$71,$B6,Data!$B$2:$B$71,TEXT(J4,"mmmm")),2),"")
B7: ITEM02 | C7: Dialyzer 1.7L | D7: =IF(SUMIFS(Data!$D$2:$D$71,Data!$F$2:$F$71,$B7,Data!$B$2:$B$71,TEXT(D4,"mmmm"))=0,"",SUMIFS(Data!$D$2:$D$71,Data!$F$2:$F$71,$B7,Data!$B$2:$B$71,TEXT(D4,"mmmm"))) | E7: =IFERROR(ROUND(AVERAGEIFS(Data!$E$2:$E$71,Data!$F$2:$F$71,$B7,Data!$B$2:$B$71,TEXT(D4,"mmmm")),2),"") | F7: =IF(SUMIFS(Data!$D$2:$D$71,Data!$F$2:$F$71,$B7,Data!$B$2:$B$71,TEXT(F4,"mmmm"))=0,"",SUMIFS(Data!$D$2:$D$71,Data!$F$2:$F$71,$B7,Data!$B$2:$B$71,TEXT(F4,"mmmm"))) -> 180 | G7: =IFERROR(ROUND(AVERAGEIFS(Data!$E$2:$E$71,Data!$F$2:$F$71,$B7,Data!$B$2:$B$71,TEXT(F4,"mmmm")),2),"") -> 690 | H7: =IF(SUMIFS(Data!$D$2:$D$71,Data!$F$2:$F$71,$B7,Data!$B$2:$B$71,TEXT(H4,"mmmm"))=0,"",SUMIFS(Data!$D$2:$D$71,Data!$F$2:$F$71,$B7,Data!$B$2:$B$71,TEXT(H4,"mmmm"))) -> 570 | I7: =IFERROR(ROUND(AVERAGEIFS(Data!$E$2:$E$71,Data!$F$2:$F$71,$B7,Data!$B$2:$B$71,TEXT(H4,"mmmm")),2),"") -> 353400 | J7: =IF(SUMIFS(Data!$D$2:$D$71,Data!$F$2:$F$71,$B7,Data!$B$2:$B$71,TEXT(J4,"mmmm"))=0,"",SUMIFS(Data!$D$2:$D$71,Data!$F$2:$F$71,$B7,Data!$B$2:$B$71,TEXT(J4,"mmmm"))) | K7: =IFERROR(ROUND(AVERAGEIFS(Data!$E$2:$E$71,Data!$F$2:$F$71,$B7,Data!$B$2:$B$71,TEXT(J4,"mmmm")),2),"")
B8: ITEM03 | C8: Dialyzer 1.5H | D8: =IF(SUMIFS(Data!$D$2:$D$71,Data!$F$2:$F$71,$B8,Data!$B$2:$B$71,TEXT(D4,"mmmm"))=0,"",SUMIFS(Data!$D$2:$D$71,Data!$F$2:$F$71,$B8,Data!$B$2:$B$71,TEXT(D4,"mmmm"))) -> 60 | E8: =IFERROR(ROUND(AVERAGEIFS(Data!$E$2:$E$71,Data!$F$2:$F$71,$B8,Data!$B$2:$B$71,TEXT(D4,"mmmm")),2),"") -> 700 | F8: =IF(SUMIFS(Data!$D$2:$D$71,Data!$F$2:$F$71,$B8,Data!$B$2:$B$71,TEXT(F4,"mmmm"))=0,"",SUMIFS(Data!$D$2:$D$71,Data!$F$2:$F$71,$B8,Data!$B$2:$B$71,TEXT(F4,"mmmm"))) | G8: =IFERROR(ROUND(AVERAGEIFS(Data!$E$2:$E$71,Data!$F$2:$F$71,$B8,Data!$B$2:$B$71,TEXT(F4,"mmmm")),2),"") | H8: =IF(SUMIFS(Data!$D$2:$D$71,Data!$F$2:$F$71,$B8,Data!$B$2:$B$71,TEXT(H4,"mmmm"))=0,"",SUMIFS(Data!$D$2:$D$71,Data!$F$2:$F$71,$B8,Data!$B$2:$B$71,TEXT(H4,"mmmm"))) -> 240 | I8: =IFERROR(ROUND(AVERAGEIFS(Data!$E$2:$E$71,Data!$F$2:$F$71,$B8,Data!$B$2:$B$71,TEXT(H4,"mmmm")),2),"") -> 688 | J8: =IF(SUMIFS(Data!$D$2:$D$71,Data!$F$2:$F$71,$B8,Data!$B$2:$B$71,TEXT(J4,"mmmm"))=0,"",SUMIFS(Data!$D$2:$D$71,Data!$F$2:$F$71,$B8,Data!$B$2:$B$71,TEXT(J4,"mmmm"))) -> 90 | K8: =IFERROR(ROUND(AVERAGEIFS(Data!$E$2:$E$71,Data!$F$2:$F$71,$B8,Data!$B$2:$B$71,TEXT(J4,"mmmm")),2),"") -> 703.33
B9: ITEM04 | C9: Dialyzer 1.5L | D9: =IF(SUMIFS(Data!$D$2:$D$71,Data!$F$2:$F$71,$B9,Data!$B$2:$B$71,TEXT(D4,"mmmm"))=0,"",SUMIFS(Data!$D$2:$D$71,Data!$F$2:$F$71,$B9,Data!$B$2:$B$71,TEXT(D4,"mmmm"))) -> 90 | E9: =IFERROR(ROUND(AVERAGEIFS(Data!$E$2:$E$71,Data!$F$2:$F$71,$B9,Data!$B$2:$B$71,TEXT(D4,"mmmm")),2),"") -> 696.67 | F9: =IF(SUMIFS(Data!$D$2:$D$71,Data!$F$2:$F$71,$B9,Data!$B$2:$B$71,TEXT(F4,"mmmm"))=0,"",SUMIFS(Data!$D$2:$D$71,Data!$F$2:$F$71,$B9,Data!$B$2:$B$71,TEXT(F4,"mmmm"))) | G9: =IFERROR(ROUND(AVERAGEIFS(Data!$E$2:$E$71,Data!$F$2:$F$71,$B9,Data!$B$2:$B$71,TEXT(F4,"mmmm")),2),"") | H9: =IF(SUMIFS(Data!$D$2:$D$71,Data!$F$2:$F$71,$B9,Data!$B$2:$B$71,TEXT(H4,"mmmm"))=0,"",SUMIFS(Data!$D$2:$D$71,Data!$F$2:$F$71,$B9,Data!$B$2:$B$71,TEXT(H4,"mmmm"))) -> 30 | I9: =IFERROR(ROUND(AVERAGEIFS(Data!$E$2:$E$71,Data!$F$2:$F$71,$B9,Data!$B$2:$B$71,TEXT(H4,"mmmm")),2),"") -> 680 | J9: =IF(SUMIFS(Data!$D$2:$D$71,Data!$F$2:$F$71,$B9,Data!$B$2:$B$71,TEXT(J4,"mmmm"))=0,"",SUMIFS(Data!$D$2:$D$71,Data!$F$2:$F$71,$B9,Data!$B$2:$B$71,TEXT(J4,"mmmm"))) | K9: =IFERROR(ROUND(AVERAGEIFS(Data!$E$2:$E$71,Data!$F$2:$F$71,$B9,Data!$B$2:$B$71,TEXT(J4,"mmmm")),2),"")
B10: ITEM05 | C10: Dialyzer 1.6H | D10: =IF(SUMIFS(Data!$D$2:$D$71,Data!$F$2:$F$71,$B10,Data!$B$2:$B$71,TEXT(D4,"mmmm"))=0,"",SUMIFS(Data!$D$2:$D$71,Data!$F$2:$F$71,$B10,Data!$B$2:$B$71,TEXT(D4,"mmmm"))) -> 60 | E10: =IFERROR(ROUND(AVERAGEIFS(Data!$E$2:$E$71,Data!$F$2:$F$71,$B10,Data!$B$2:$B$71,TEXT(D4,"mmmm")),2),"") -> 700 | F10: =IF(SUMIFS(Data!$D$2:$D$71,Data!$F$2:$F$71,$B10,Data!$B$2:$B$71,TEXT(F4,"mmmm"))=0,"",SUMIFS(Data!$D$2:$D$71,Data!$F$2:$F$71,$B10,Data!$B$2:$B$71,TEXT(F4,"mmmm"))) -> 120 | G10: =IFERROR(ROUND(AVERAGEIFS(Data!$E$2:$E$71,Data!$F$2:$F$71,$B10,Data!$B$2:$B$71,TEXT(F4,"mmmm")),2),"") -> 682.5 | H10: =IF(SUMIFS(Data!$D$2:$D$71,Data!$F$2:$F$71,$B10,Data!$B$2:$B$71,TEXT(H4,"mmmm"))=0,"",SUMIFS(Data!$D$2:$D$71,Data!$F$2:$F$71,$B10,Data!$B$2:$B$71,TEXT(H4,"mmmm"))) -> 150 | I10: =IFERROR(ROUND(AVERAGEIFS(Data!$E$2:$E$71,Data!$F$2:$F$71,$B10,Data!$B$2:$B$71,TEXT(H4,"mmmm")),2),"") -> 37540 | J10: =IF(SUMIFS(Data!$D$2:$D$71,Data!$F$2:$F$71,$B10,Data!$B$2:$B$71,TEXT(J4,"mmmm"))=0,"",SUMIFS(Data!$D$2:$D$71,Data!$F$2:$F$71,$B10,Data!$B$2:$B$71,TEXT(J4,"mmmm"))) | K10: =IFERROR(ROUND(AVERAGEIFS(Data!$E$2:$E$71,Data!$F$2:$F$71,$B10,Data!$B$2:$B$71,TEXT(J4,"mmmm")),2),"")
B11: ITEM06 | C11: Dialyzer 1.6L | D11: =IF(SUMIFS(Data!$D$2:$D$71,Data!$F$2:$F$71,$B11,Data!$B$2:$B$71,TEXT(D4,"mmmm"))=0,"",SUMIFS(Data!$D$2:$D$71,Data!$F$2:$F$71,$B11,Data!$B$2:$B$71,TEXT(D4,"mmmm"))) | E11: =IFERROR(ROUND(AVERAGEIFS(Data!$E$2:$E$71,Data!$F$2:$F$71,$B11,Data!$B$2:$B$71,TEXT(D4,"mmmm")),2),"") | F11: =IF(SUMIFS(Data!$D$2:$D$71,Data!$F$2:$F$71,$B11,Data!$B$2:$B$71,TEXT(F4,"mmmm"))=0,"",SUMIFS(Data!$D$2:$D$71,Data!$F$2:$F$71,$B11,Data!$B$2:$B$71,TEXT(F4,"mmmm"))) -> 30 | G11: =IFERROR(ROUND(AVERAGEIFS(Data!$E$2:$E$71,Data!$F$2:$F$71,$B11,Data!$B$2:$B$71,TEXT(F4,"mmmm")),2),"") -> 680 | H11: =IF(SUMIFS(Data!$D$2:$D$71,Data!$F$2:$F$71,$B11,Data!$B$2:$B$71,TEXT(H4,"mmmm"))=0,"",SUMIFS(Data!$D$2:$D$71,Data!$F$2:$F$71,$B11,Data!$B$2:$B$71,TEXT(H4,"mmmm"))) -> 60 | I11: =IFERROR(ROUND(AVERAGEIFS(Data!$E$2:$E$71,Data!$F$2:$F$71,$B11,Data!$B$2:$B$71,TEXT(H4,"mmmm")),2),"") -> 9640 | J11: =IF(SUMIFS(Data!$D$2:$D$71,Data!$F$2:$F$71,$B11,Data!$B$2:$B$71,TEXT(J4,"mmmm"))=0,"",SUMIFS(Data!$D$2:$D$71,Data!$F$2:$F$71,$B11,Data!$B$2:$B$71,TEXT(J4,"mmmm"))) | K11: =IFERROR(ROUND(AVERAGEIFS(Data!$E$2:$E$71,Data!$F$2:$F$71,$B11,Data!$B$2:$B$71,TEXT(J4,"mmmm")),2),"")
B12: ITEM07 | C12: Dialyzer 1.8H | D12: =IF(SUMIFS(Data!$D$2:$D$71,Data!$F$2:$F$71,$B12,Data!$B$2:$B$71,TEXT(D4,"mmmm"))=0,"",SUMIFS(Data!$D$2:$D$71,Data!$F$2:$F$71,$B12,Data!$B$2:$B$71,TEXT(D4,"mmmm"))) | E12: =IFERROR(ROUND(AVERAGEIFS(Data!$E$2:$E$71,Data!$F$2:$F$71,$B12,Data!$B$2:$B$71,TEXT(D4,"mmmm")),2),"") | F12: =IF(SUMIFS(Data!$D$2:$D$71,Data!$F$2:$F$71,$B12,Data!$B$2:$B$71,TEXT(F4,"mmmm"))=0,"",SUMIFS(Data!$D$2:$D$71,Data!$F$2:$F$71,$B12,Data!$B$2:$B$71,TEXT(F4,"mmmm"))) | G12: =IFERROR(ROUND(AVERAGEIFS(Data!$E$2:$E$71,Data!$F$2:$F$71,$B12,Data!$B$2:$B$71,TEXT(F4,"mmmm")),2),"") | H12: =IF(SUMIFS(Data!$D$2:$D$71,Data!$F$2:$F$71,$B12,Data!$B$2:$B$71,TEXT(H4,"mmmm"))=0,"",SUMIFS(Data!$D$2:$D$71,Data!$F$2:$F$71,$B12,Data!$B$2:$B$71,TEXT(H4,"mmmm"))) -> 150 | I12: =IFERROR(ROUND(AVERAGEIFS(Data!$E$2:$E$71,Data!$F$2:$F$71,$B12,Data!$B$2:$B$71,TEXT(H4,"mmmm")),2),"") -> 93000 | J12: =IF(SUMIFS(Data!$D$2:$D$71,Data!$F$2:$F$71,$B12,Data!$B$2:$B$71,TEXT(J4,"mmmm"))=0,"",SUMIFS(Data!$D$2:$D$71,Data!$F$2:$F$71,$B12,Data!$B$2:$B$71,TEXT(J4,"mmmm"))) | K12: =IFERROR(ROUND(AVERAGEIFS(Data!$E$2:$E$71,Data!$F$2:$F$71,$B12,Data!$B$2:$B$71,TEXT(J4,"mmmm")),2),"")
B13: ITEM09 | C13: Dialyzer | D13: =IF(SUMIFS(Data!$D$2:$D$71,Data!$F$2:$F$71,$B13,Data!$B$2:$B$71,TEXT(D4,"mmmm"))=0,"",SUMIFS(Data!$D$2:$D$71,Data!$F$2:$F$71,$B13,Data!$B$2:$B$71,TEXT(D4,"mmmm"))) -> 30 | E13: =IFERROR(ROUND(AVERAGEIFS(Data!$E$2:$E$71,Data!$F$2:$F$71,$B13,Data!$B$2:$B$71,TEXT(D4,"mmmm")),2),"") -> 690 | F13: =IF(SUMIFS(Data!$D$2:$D$71,Data!$F$2:$F$71,$B13,Data!$B$2:$B$71,TEXT(F4,"mmmm"))=0,"",SUMIFS(Data!$D$2:$D$71,Data!$F$2:$F$71,$B13,Data!$B$2:$B$71,TEXT(F4,"mmmm"))) | G13: =IFERROR(ROUND(AVERAGEIFS(Data!$E$2:$E$71,Data!$F$2:$F$71,$B13,Data!$B$2:$B$71,TEXT(F4,"mmmm")),2),"") | H13: =IF(SUMIFS(Data!$D$2:$D$71,Data!$F$2:$F$71,$B13,Data!$B$2:$B$71,TEXT(H4,"mmmm"))=0,"",SUMIFS(Data!$D$2:$D$71,Data!$F$2:$F$71,$B13,Data!$B$2:$B$71,TEXT(H4,"mmmm"))) -> 210 | I13: =IFERROR(ROUND(AVERAGEIFS(Data!$E$2:$E$71,Data!$F$2:$F$71,$B13,Data!$B$2:$B$71,TEXT(H4,"mmmm")),2),"") -> 130200 | J13: =IF(SUMIFS(Data!$D$2:$D$71,Data!$F$2:$F$71,$B13,Data!$B$2:$B$71,TEXT(J4,"mmmm"))=0,"",SUMIFS(Data!$D$2:$D$71,Data!$F$2:$F$71,$B13,Data!$B$2:$B$71,TEXT(J4,"mmmm"))) | K13: =IFERROR(ROUND(AVERAGEIFS(Data!$E$2:$E$71,Data!$F$2:$F$71,$B13,Data!$B$2:$B$71,TEXT(J4,"mmmm")),2),"")
B14: ITEM08 | C14: Dialyzer | D14: =IF(SUMIFS(Data!$D$2:$D$71,Data!$F$2:$F$71,$B14,Data!$B$2:$B$71,TEXT(D4,"mmmm"))=0,"",SUMIFS(Data!$D$2:$D$71,Data!$F$2:$F$71,$B14,Data!$B$2:$B$71,TEXT(D4,"mmmm"))) | E14: =IFERROR(ROUND(AVERAGEIFS(Data!$E$2:$E$71,Data!$F$2:$F$71,$B14,Data!$B$2:$B$71,TEXT(D4,"mmmm")),2),"") | F14: =IF(SUMIFS(Data!$D$2:$D$71,Data!$F$2:$F$71,$B14,Data!$B$2:$B$71,TEXT(F4,"mmmm"))=0,"",SUMIFS(Data!$D$2:$D$71,Data!$F$2:$F$71,$B14,Data!$B$2:$B$71,TEXT(F4,"mmmm"))) | G14: =IFERROR(ROUND(AVERAGEIFS(Data!$E$2:$E$71,Data!$F$2:$F$71,$B14,Data!$B$2:$B$71,TEXT(F4,"mmmm")),2),"") | H14: =IF(SUMIFS(Data!$D$2:$D$71,Data!$F$2:$F$71,$B14,Data!$B$2:$B$71,TEXT(H4,"mmmm"))=0,"",SUMIFS(Data!$D$2:$D$71,Data!$F$2:$F$71,$B14,Data!$B$2:$B$71,TEXT(H4,"mmmm"))) -> 30 | I14: =IFERROR(ROUND(AVERAGEIFS(Data!$E$2:$E$71,Data!$F$2:$F$71,$B14,Data!$B$2:$B$71,TEXT(H4,"mmmm")),2),"") -> 680 | J14: =IF(SUMIFS(Data!$D$2:$D$71,Data!$F$2:$F$71,$B14,Data!$B$2:$B$71,TEXT(J4,"mmmm"))=0,"",SUMIFS(Data!$D$2:$D$71,Data!$F$2:$F$71,$B14,Data!$B$2:$B$71,TEXT(J4,"mmmm"))) | K14: =IFERROR(ROUND(AVERAGEIFS(Data!$E$2:$E$71,Data!$F$2:$F$71,$B14,Data!$B$2:$B$71,TEXT(J4,"mmmm")),2),"")
B15: ITEM10 | C15: Blood Line Sets | D15: =IF(SUMIFS(Data!$D$2:$D$71,Data!$F$2:$F$71,$B15,Data!$B$2:$B$71,TEXT(D4,"mmmm"))=0,"",SUMIFS(Data!$D$2:$D$71,Data!$F$2:$F$71,$B15,Data!$B$2:$B$71,TEXT(D4,"mmmm"))) -> 270 | E15: =IFERROR(ROUND(AVERAGEIFS(Data!$E$2:$E$71,Data!$F$2:$F$71,$B15,Data!$B$2:$B$71,TEXT(D4,"mmmm")),2),"") -> 231.67 | F15: =IF(SUMIFS(Data!$D$2:$D$71,Data!$F$2:$F$71,$B15,Data!$B$2:$B$71,TEXT(F4,"mmmm"))=0,"",SUMIFS(Data!$D$2:$D$71,Data!$F$2:$F$71,$B15,Data!$B$2:$B$71,TEXT(F4,"mmmm"))) -> 660 | G15: =IFERROR(ROUND(AVERAGEIFS(Data!$E$2:$E$71,Data!$F$2:$F$71,$B15,Data!$B$2:$B$71,TEXT(F4,"mmmm")),2),"") -> 226.67 | H15: =IF(SUMIFS(Data!$D$2:$D$71,Data!$F$2:$F$71,$B15,Data!$B$2:$B$71,TEXT(H4,"mmmm"))=0,"",SUMIFS(Data!$D$2:$D$71,Data!$F$2:$F$71,$B15,Data!$B$2:$B$71,TEXT(H4,"mmmm"))) -> 800 | I15: =IFERROR(ROUND(AVERAGEIFS(Data!$E$2:$E$71,Data!$F$2:$F$71,$B15,Data!$B$2:$B$71,TEXT(H4,"mmmm")),2),"") -> 321.67 | J15: =IF(SUMIFS(Data!$D$2:$D$71,Data!$F$2:$F$71,$B15,Data!$B$2:$B$71,TEXT(J4,"mmmm"))=0,"",SUMIFS(Data!$D$2:$D$71,Data!$F$2:$F$71,$B15,Data!$B$2:$B$71,TEXT(J4,"mmmm"))) -> 420 | K15: =IFERROR(ROUND(AVERAGEIFS(Data!$E$2:$E$71,Data!$F$2:$F$71,$B15,Data!$B$2:$B$71,TEXT(J4,"mmmm")),2),"") -> 218.75
B16: ITEM11 | C16: AV Fistula 16g | D16: =IF(SUMIFS(Data!$D$2:$D$71,Data!$F$2:$F$71,$B16,Data!$B$2:$B$71,TEXT(D4,"mmmm"))=0,"",SUMIFS(Data!$D$2:$D$71,Data!$F$2:$F$71,$B16,Data!$B$2:$B$71,TEXT(D4,"mmmm"))) -> 180 | E16: =IFERROR(ROUND(AVERAGEIFS(Data!$E$2:$E$71,Data!$F$2:$F$71,$B16,Data!$B$2:$B$71,TEXT(D4,"mmmm")),2),"") -> 60.58 | F16: =IF(SUMIFS(Data!$D$2:$D$71,Data!$F$2:$F$71,$B16,Data!$B$2:$B$71,TEXT(F4,"mmmm"))=0,"",SUMIFS(Data!$D$2:$D$71,Data!$F$2:$F$71,$B16,Data!$B$2:$B$71,TEXT(F4,"mmmm"))) -> 550 | G16: =IFERROR(ROUND(AVERAGEIFS(Data!$E$2:$E$71,Data!$F$2:$F$71,$B16,Data!$B$2:$B$71,TEXT(F4,"mmmm")),2),"") -> 55 | H16: =IF(SUMIFS(Data!$D$2:$D$71,Data!$F$2:$F$71,$B16,Data!$B$2:$B$71,TEXT(H4,"mmmm"))=0,"",SUMIFS(Data!$D$2:$D$71,Data!$F$2:$F$71,$B16,Data!$B$2:$B$71,TEXT(H4,"mmmm"))) | I16: =IFERROR(ROUND(AVERAGEIFS(Data!$E$2:$E$71,Data!$F$2:$F$71,$B16,Data!$B$2:$B$71,TEXT(H4,"mmmm")),2),"") | J16: =IF(SUMIFS(Data!$D$2:$D$71,Data!$F$2:$F$71,$B16,Data!$B$2:$B$71,TEXT(J4,"mmmm"))=0,"",SUMIFS(Data!$D$2:$D$71,Data!$F$2:$F$71,$B16,Data!$B$2:$B$71,TEXT(J4,"mmmm"))) | K16: =IFERROR(ROUND(AVERAGEIFS(Data!$E$2:$E$71,Data!$F$2:$F$71,$B16,Data!$B$2:$B$71,TEXT(J4,"mmmm")),2),"") | L16: 1000 | M16: 52
B17: ITEM12 | C17: AV Fistula 17g | D17: =IF(SUMIFS(Data!$D$2:$D$71,Data!$F$2:$F$71,$B17,Data!$B$2:$B$71,TEXT(D4,"mmmm"))=0,"",SUMIFS(Data!$D$2:$D$71,Data!$F$2:$F$71,$B17,Data!$B$2:$B$71,TEXT(D4,"mmmm"))) -> 30 | E17: =IFERROR(ROUND(AVERAGEIFS(Data!$E$2:$E$71,Data!$F$2:$F$71,$B17,Data!$B$2:$B$71,TEXT(D4,"mmmm")),2),"") -> 60 | F17: =IF(SUMIFS(Data!$D$2:$D$71,Data!$F$2:$F$71,$B17,Data!$B$2:$B$71,TEXT(F4,"mmmm"))=0,"",SUMIFS(Data!$D$2:$D$71,Data!$F$2:$F$71,$B17,Data!$B$2:$B$71,TEXT(F4,"mmmm"))) | G17: =IFERROR(ROUND(AVERAGEIFS(Data!$E$2:$E$71,Data!$F$2:$F$71,$B17,Data!$B$2:$B$71,TEXT(F4,"mmmm")),2),"") | H17: =IF(SUMIFS(Data!$D$2:$D$71,Data!$F$2:$F$71,$B17,Data!$B$2:$B$71,TEXT(H4,"mmmm"))=0,"",SUMIFS(Data!$D$2:$D$71,Data!$F$2:$F$71,$B17,Data!$B$2:$B$71,TEXT(H4,"mmmm"))) | I17: =IFERROR(ROUND(AVERAGEIFS(Data!$E$2:$E$71,Data!$F$2:$F$71,$B17,Data!$B$2:$B$71,TEXT(H4,"mmmm")),2),"") | J17: =IF(SUMIFS(Data!$D$2:$D$71,Data!$F$2:$F$71,$B17,Data!$B$2:$B$71,TEXT(J4,"mmmm"))=0,"",SUMIFS(Data!$D$2:$D$71,Data!$F$2:$F$71,$B17,Data!$B$2:$B$71,TEXT(J4,"mmmm"))) | K17: =IFERROR(ROUND(AVERAGEIFS(Data!$E$2:$E$71,Data!$F$2:$F$71,$B17,Data!$B$2:$B$71,TEXT(J4,"mmmm")),2),"")
B18: ITEM13 | C18: Catheter | D18: =IF(SUMIFS(Data!$D$2:$D$71,Data!$F$2:$F$71,$B18,Data!$B$2:$B$71,TEXT(D4,"mmmm"))=0,"",SUMIFS(Data!$D$2:$D$71,Data!$F$2:$F$71,$B18,Data!$B$2:$B$71,TEXT(D4,"mmmm"))) -> 10 | E18: =IFERROR(ROUND(AVERAGEIFS(Data!$E$2:$E$71,Data!$F$2:$F$71,$B18,Data!$B$2:$B$71,TEXT(D4,"mmmm")),2),"") -> 1300 | F18: =IF(SUMIFS(Data!$D$2:$D$71,Data!$F$2:$F$71,$B18,Data!$B$2:$B$71,TEXT(F4,"mmmm"))=0,"",SUMIFS(Data!$D$2:$D$71,Data!$F$2:$F$71,$B18,Data!$B$2:$B$71,TEXT(F4,"mmmm"))) -> 80 | G18: =IFERROR(ROUND(AVERAGEIFS(Data!$E$2:$E$71,Data!$F$2:$F$71,$B18,Data!$B$2:$B$71,TEXT(F4,"mmmm")),2),"") -> 1300 | H18: =IF(SUMIFS(Data!$D$2:$D$71,Data!$F$2:$F$71,$B18,Data!$B$2:$B$71,TEXT(H4,"mmmm"))=0,"",SUMIFS(Data!$D$2:$D$71,Data!$F$2:$F$71,$B18,Data!$B$2:$B$71,TEXT(H4,"mmmm"))) -> 250 | I18: =IFERROR(ROUND(AVERAGEIFS(Data!$E$2:$E$71,Data!$F$2:$F$71,$B18,Data!$B$2:$B$71,TEXT(H4,"mmmm")),2),"") -> 250 | J18: =IF(SUMIFS(Data!$D$2:$D$71,Data!$F$2:$F$71,$B18,Data!$B$2:$B$71,TEXT(J4,"mmmm"))=0,"",SUMIFS(Data!$D$2:$D$71,Data!$F$2:$F$71,$B18,Data!$B$2:$B$71,TEXT(J4,"mmmm"))) | K18: =IFERROR(ROUND(AVERAGEIFS(Data!$E$2:$E$71,Data!$F$2:$F$71,$B18,Data!$B$2:$B$71,TEXT(J4,"mmmm")),2),"")
C19: Total Qty (all items) | D19: =SUM(D6:D18) -> 850 | F19: =SUM(F6:F18) -> 1950 | H19: =SUM(H6:H18) -> 3626 | J19: =SUM(J6:J18) -> 510 | L19: =SUM(L6:L18) -> 1000 | M19: =SUM(M6:M18) -> 52

Sheet ARK Hospital
C2: Party Name
A4: Party Name | B4: Month | C4: Sales Date | D4: Item | E4: Qty | F4: Unit Price | G4: Total Price | H4: Paid Amount | I4: Dues Amount | J4: Discount | K4: Total Amount After Discount | L4: Collection Date | M4: Collection Amount | N4: Remarks
A5: Ark Hospital | B5: April | C5: 18/4/2026 | D5: Dialyzer 1.7H | E5: 60 | F5: 680 | G5: 40800 | H5: 40800 | I5: 0 | K5: =IF(J5>0,G5-J5,"")
D6: Blood Line Sets | E6: 30 | F6: 230 | G6: 6900 | H6: 6900 | I6: 0 | K6: =IF(J6>0,G6-J6,"")
C7: 22/4/2026 | D7: Central Vanous Cather 7Fr-13cm | E7: 10 | F7: 1300 | G7: 13000 | H7: 13000 | I7: 0 | K7: =IF(J7>0,G7-J7,"")
F8: Total | G8: =SUM(G5:G7)-SUM(J5:J7) -> 60700 | H8: =H5+H6+H7 -> 60700 | I8: =I18 -> 0 | J8: =SUM(J5:J7) -> 0 | K8: =G8 -> 60700
B10: Month | C10: Sales Date | D10: Item | E10: Qty | F10: Unit Price | G10: Total Price | H10: Paid Amount | I10: Dues Amount | J10: Discount | K10: Total Amount After Discount | L10: Collection Date | M10: Collection Amount | N10: Remarks
B11: May | C11: 46058 | D11: Dialyzer 1.7H | E11: 90 | F11: 680 | G11: 61200 | H11: 61200 | I11: 0 | K11: =IF(J11>0,G11-J11,"") | L11: 46058 | M11: 68100
D12: Blood Line Sets | E12: 30 | F12: 230 | G12: 6900 | H12: 6900 | I12: 0 | K12: =IF(J12>0,G12-J12,"")
C13: 46331 | D13: Dialyzer 1.7H | E13: 60 | F13: 680 | G13: 40800 | H13: 40800 | I13: 0 | K13: =IF(J13>0,G13-J13,"") | L13: 46331 | M13: 47700
D14: Blood Line Sets | E14: 30 | F14: 230 | G14: 6900 | H14: 6900 | I14: 0 | K14: =IF(J14>0,G14-J14,"")
C15: 23/5/2026 | D15: Dialyzer 1.7H | E15: 30 | F15: 680 | G15: 20400 | H15: 20400 | I15: 0 | K15: =IF(J15>0,G15-J15,"") | L15: 23/5/2026 | M15: 47700
D16: Dialyzer 1.7L | E16: 30 | F16: 680 | G16: 20400 | H16: 20400 | I16: 0 | K16: =IF(J16>0,G16-J16,"")
D17: Blood Line Sets | E17: 30 | F17: 230 | G17: 6900 | H17: 6900 | I17: 0 | K17: =IF(J17>0,G17-J17,"")
F18: Total | G18: =SUM(G11:G17)-SUM(J11:J17) -> 163500 | H18: =SUM(H11:H17) -> 163500 | I18: =IF(AND(G18="", H18=""), "", G2-H2) -> 0 | J18: =SUM(J9:J17) -> 0 | K18: =G18 -> 163500
B20: Month | C20: Sales Date | D20: Item | E20: Qty | F20: Unit Price | G20: Total Price | H20: Paid Amount | I20: Dues Amount | J20: Discount | K20: Total Amount After Discount | L20: Collection Date | M20: Collection Amount | N20: Remarks
B21: June | C21: 46240 | D21: Dialyzer 1.5H | E21: 60 | F21: 680 | G21: 40800 | H21: 40800 | I21: =IF(AND(G21="",H21=""),"",G21-H21) -> 0 | K21: =IF(J21>0,G21-J21,"") | L21: 46271 | M21: 61200
D22: Dialyzer 2.0 | E22: 30 | F22: 680 | G22: 20400 | H22: 20400 | I22: =IF(AND(G22="",H22=""),"",G22-H22) -> 0 | K22: =IF(J22>0,G22-J22,"")
C23: 17/6/26 | D23: Dialyzer 1.5H | E23: 60 | F23: 680 | G23: 40800 | H23: 40800 | I23: =IF(AND(G23="",H23=""),"",G23-H23) -> 0 | K23: =IF(J23>0,G23-J23,"") | L23: 17/6/2026 | M23: 40800 | N23: (House rent 20,000 from this collection)
C24: 24/6/26 | D24: Dialyzer 1.5H | E24: 60 | F24: 680 | G24: 40800 | H24: 40800 | I24: =IF(AND(G24="",H24=""),"",G24-H24) -> 0 | K24: =IF(J24>0,G24-J24,"") | L24: 24/6/2026 | M24: 40800
F25: Total | G25: =SUM(G21:G24)-SUM(J21:J24) -> 142800 | H25: =SUM(H21:H24) -> 142800 | I25: =IF(AND(G25="", H25=""), "", G25-H25) -> 0 | J25: =SUM(J19:J24) -> 0 | K25: =G25 -> 142800 | L25: Total | M25: =SUM(M21:M24) -> 142800

Sheet Bismillah Surgical
A3: Party Name | B3: Month | C3: Sales Date | D3: Item | E3: Qty | F3: Unit Price | G3: Total Price | H3: Paid Amount | I3: Dues Amount | J3: Discount | K3: Total Amount After Discount | L3: Collection Date | M3: Collection Amount | N3: Remarks
A4: Bismillah Surgical | B4: April | C4: 28/4/2026 | D4: Dialyzer 1.5H | E4: 30 | F4: 700 | G4: 21000 | H4: 21000 | I4: 0 | K4: =IF(J4>0,G4-J4,"")
D5: Dialyzer 1.5L | E5: 30 | F5: 700 | G5: 21000 | H5: 21000 | I5: 0 | K5: =IF(J5>0,G5-J5,"")
D6: Blood Line Sets | E6: 60 | F6: 230 | G6: 13800 | H6: 13800 | I6: =IF(AND(G6="", H6=""), "", G4-H4) -> 0 | K6: =IF(J6>0,G6-J6,"")
D7: AV Fistula 16g | E7: 50 | F7: 60 | G7: 3000 | H7: 3000 | I7: =IF(AND(G7="", H7=""), "", G5-H5) -> 0 | K7: =IF(J7>0,G7-J7,"") | L7: 46331 | M7: 10000 | N7: Loan for Driver & Car fueling
D8: AV Fistula 17g | E8: 30 | F8: 60 | G8: 1800 | H8: 1800 | I8: =IF(AND(G8="", H8=""), "", G6-H6) -> 0 | K8: =IF(J8>0,G8-J8,"") | L8: 25/5/2026 | M8: 10000
D9: AV Fistula Needle for Hemodialysis | E9: 80 | F9: 60 | G9: 4800 | H9: 4800 | I9: =IF(AND(G9="", H9=""), "", G7-H7) -> 0 | K9: =IF(J9>0,G9-J9,"")
D10: Dialyzer for Hemodialysis 1.5H | E10: 30 | F10: 700 | G10: 21000 | H10: 21000 | I10: =IF(AND(G10="", H10=""), "", G8-H8) -> 0 | K10: =IF(J10>0,G10-J10,"") | L10: 23/6/2026 | M10: 10000
D11: Dialyzer For Hemodialysis 1.5L | E11: 30 | F11: 700 | G11: 21000 | H11: 21000 | I11: =IF(AND(G11="", H11=""), "", G9-H9) -> 0 | K11: =IF(J11>0,G11-J11,"")
D12: Blood Tubing Set For Hemodialysis | E12: 60 | F12: 230 | G12: 13800 | H12: 13800 | I12: =IF(AND(G12="", H12=""), "", G10-H10) -> 0 | K12: =IF(J12>0,G12-J12,"")
F13: Total | G13: =SUM(G4:G12)-SUM(J4:J12) -> 121200 | H13: =SUM(H4:H12) -> 121200 | I13: =IF(AND(G13="", H13=""), "", G11-H11) -> 0 | J13: =SUM(J4:J12) -> 0 | K13: =G13 -> 121200 | L13: Total | M13: =SUM(M4:M12) -> 30000

Sheet Popular Medcine & Departmental 
A5: Party Name | B5: Month | C5: Sales Date | D5: Item | E5: Qty | F5: Unit Price | G5: Total Price | H5: Paid Amount | I5: Dues Amount | J5: Discount | K5: Total Amount After Discount | L5: Collection Date | M5: Collection Amount | N5: Remarks
A6: Popular Medicine AND Departmental Store | B6: April | C6: 20/4/2026 | D6: Dialyzer For Hemodialysis 1.5L | E6: 30 | F6: 690 | G6: 20700 | H6: 20700 | I6: 0 | K6: =IF(J6>0,G6-J6,"") | L6: 14/5/2026 | M6: 30987
D7: Blood Tubing Set For Hemodialysis | E7: 30 | F7: 240 | G7: 7200 | H7: 7200 | I7: 0 | K7: =IF(J7>0,G7-J7,"")
D8: AV Fistula 16g | E8: 50 | F8: 61.74 | G8: 3087 | H8: 3087 | I8: 0 | K8: =IF(J8>0,G8-J8,"")
F9: Total | G9: =SUM(G6:G8)-SUM(J6:J8) -> 30987 | H9: =SUM(H6:H8) -> 30987 | I9: =SUM(I6:I8) -> 0 | J9: =SUM(J6:J8) -> 0 | K9: =G9 -> 30987
G10: Total Paid | H10: 30987-1400= 29,587 ( VAT of Bank 1400) | K10: =IF(J10>0,G10-J10,"")
C11: June
B12: Month | C12: Sales Date | D12: Item | E12: Qty | F12: Unit Price | G12: Total Price | H12: Paid Amount | I12: Dues Amount | J12: Discount | K12: Total Amount After Discount | L12: Collection Date | M12: Collection Amount | N12: Remarks
C13: 46301 | D13: Dialyzer 1.5H | E13: 30 | F13: 700 | G13: 21000 | H13: 21000 | I13: 0 | K13: =IF(J13>0,G13-J13,"") | L13: 46363 | M13: 27050 | N13: Cash forward to Mercantile Bank (13/07/2026)
D14: Blood Line Sets | E14: 30 | F14: 235 | G14: 7050 | H14: 7050 | I14: 0 | K14: =IF(J14>0,G14-J14,"")
F15: Total | G15: =SUM(G13:G14)-SUM(J13:J14) -> 28050 | H15: =SUM(H13:H14) -> 28050 | I15: 0 | J15: =SUM(J10:J14) -> 0
C17: August
B18: Month | C18: Sales Date | D18: Item | E18: Qty | F18: Unit Price | G18: Total Price | H18: Paid Amount | I18: Dues Amount | J18: Discount | K18: Total Amount After Discount | L18: Collection Date | M18: Collection Amount | N18: Remarks
C19: 46030 | D19: Dialyzer 1.5L | E19: 30 | F19: 700 | G19: 21000 | H19: 0 | I19: =IF(AND(G19="",H19=""),"", G19-H19) -> 21000 | J19: 0
D20: Blood Line Sets | E20: 30 | F20: 230 | G20: 6900 | H20: 0 | I20: =IF(AND(G20="",H20=""),"", G20-H20) -> 6900 | J20: 0
F21: Total | G21: =SUM(G19:G20)-SUM(J19:J20) -> 27900 | I21: =SUM(I19:I20) -> 27900 | K21: =G21 -> 27900

Sheet Kuwait Moitri Hospital
B6: Party Name | C6: Month | D6: Sales Date | E6: Item | F6: Qty | G6: Unit Price | H6: Total Price | I6: Paid Amount | J6: Dues Amount | K6: Discount | L6: Total Amount After Discount | M6: Collection Date | N6: Collection Amount | O6: Remarks
B7: Kuwait Moitri Hospital | C7: April | D7: 13/4/2026 | E7: Dialyzer | F7: 30 | G7: 690 | H7: 20700 | I7: 20700 | J7: 0 | L7: =IF(K7>0,H7-K7,"")
E8: Blood Line Sets | F8: 30 | G8: 230 | H8: 6900 | I8: 6900 | J8: 0 | L8: =IF(K8>0,H8-K8,"")
G9: Total | H9: =SUM(H7:H8)-SUM(K7:K8) -> 27600 | I9: =SUM(I7:I8) -> 27600 | J9: 0 | K9: =SUM(K7:K8) -> 0 | L9: =H9 -> 27600

Sheet VIP PHARMA-HAZI PHARMA
B4: Party Name | C4: Month | D4: Sales Date | E4: Item | F4: Qty | G4: Unit Price | H4: Total Price | I4: Paid Amount | J4: Dues Amount | K4: Discount | L4: Total Amount After Discount | M4: Collection Date | N4: Collection Amount | O4: Remarks
B5: VIP PHARMA-HAZI PHARMA | C5: April | D5: 21/4/2026 | E5: Dialyzer 1.7H | F5: 60 | G5: 700 | H5: 42000 | I5: 42000 | J5: 0 | M5: 22/5/2026 | N5: 8800
E6: Dialyzer 1.6H | F6: 60 | G6: 700 | H6: 42000 | I6: 42000 | J6: 0 | L6: =IF(K6>0,H6-K6,"")
E7: Blood Line Sets | F7: 60 | G7: 230 | H7: 13800 | I7: 13800 | J7: 0 | L7: =IF(K7>0,H7-K7,"")
G8: Total | H8: =SUM(H5:H7)-SUM(K5:K7) -> 97800 | I8: =SUM(I5:I7) -> 97800 | J8: =SUM(J5:J7) -> 0 | K8: =SUM(K5:K7) -> 0 | L8: =H8 -> 97800

Sheet Mr. Afjal
D3: Party Name
B5: Party Name | C5: Month | D5: Sales Date | E5: Item | F5: Qty | G5: Unit Price | H5: Total Price | I5: Paid Amount | J5: Dues Amount | K5: Discount | L5: Total Amount After Discount | M5: Collection Date | N5: Collection Amount | O5: Remarks
B6: Mr. Afjal | C6: May | D6: 46300 | E6: Dialyzer 1.6H | F6: 30 | G6: 680 | H6: =PRODUCT(F6:G6) -> 20400 | I6: 20400 | J6: =IF(AND(H6="", I6=""), "", H6-I6) -> 0 | L6: =IF(K6>0,H6-K6,"") | M6: 46300 | N6: 27300
E7: Blood Line Sets | F7: 30 | G7: 230 | H7: =PRODUCT(F7:G7) -> 6900 | I7: 6900 | J7: =IF(AND(H7="", I7=""), "", H7-I7) -> 0
D8: 19/5/2026 | E8: Dialyzer 1.7H | F8: 90 | G8: 680 | H8: =PRODUCT(F8:G8) -> 61200 | I8: 61200 | J8: 0 | L8: =IF(K8>0,H8-K8,"") | M8: 24/5/2026 | N8: 66900
E9: Blood Line Sets | F9: 90 | G9: 230 | H9: =PRODUCT(F9:G9) -> 20700 | I9: 20700 | J9: 0 | L9: =IF(K9>0,H9-K9,"") | M9: 19/5/2026 | N9: 15000
G10: Total | H10: =SUM(H6:H9)-SUM(K6:K9) -> 109200 | I10: =SUM(I6:I9) -> 109200 | J10: 0 | K10: =SUM(K6:K9) -> 0 | L10: =H10 -> 109200 | M10: Total | N10: =SUM(N6:N9) -> 109200
C12: Month | D12: Sales Date | E12: Item | F12: Qty | G12: Unit Price | H12: Total Price | I12: Paid Amount | J12: Dues Amount | K12: Discount | L12: Total Amount After Discount | M12: Collection Date | N12: Collection Amount | O12: Remarks
C13: July | D13: 46210 | E13: Blood Line Sets | F13: 120 | G13: [225]200 | H13: 24000 | I13: 24000 | J13: 0 | L13: =IF(K13>0,H13-K13,"") | M13: 46210 | N13: 24000 | O13: Cut from Saifullah Salary 3000 Taka
G14: Total | H14: =SUM(H13)-SUM(K13) -> 24000 | I14: =I13 -> 24000 | J14: =J13 -> 0 | K14: =SUM(K11:K13) -> 0 | L14: =H14 -> 24000 | M14: Total | N14: =SUM(N13) -> 24000

Sheet AR Medi Corporation
A5: Party Name | B5: Month | C5: Sales Date | D5: Item | E5: Qty | F5: Unit Price | G5: Total Price | H5: Paid Amount | I5: Dues Amount | J5: Discount | K5: Total Amount After Discount | L5: Collection Date | M5: Collection Amount | N5: Remarks
A6: Ar Medical Corporation | B6: May | C6: 46300 | D6: Dialyzer 1.6L | E6: 30 | F6: 680 | G6: 20400 | H6: 20400 | I6: 0 | K6: =IF(J6>0,G6-J6,"") | L6: 46300 | M6: 20750
D7: Blood Line Sets | E7: 30 | F7: 220 | G7: 6600 | H7: 6600 | I7: 0 | K7: =IF(J7>0,G7-J7,"")
D8: AV Fistula 16g | E8: 50 | F8: 55 | G8: 2750 | H8: 2750 | I8: 0 | K8: =IF(J8>0,G8-J8,"")
F9: Total | G9: =SUM(G6:G8)-SUM(J6:J8) -> 29750 | H9: =SUM(H6:H8) -> 29750 | I9: =SUM(I6:I8) -> 0 | J9: =SUM(J6:J8) -> 0 | K9: =G9 -> 29750
B14: Month | C14: Sales Date | D14: Item | E14: Qty | F14: Unit Price | G14: Total Price | H14: Paid Amount | I14: Dues Amount | J14: Discount | K14: Total Amount After Discount | L14: Collection Date | M14: Collection Amount | N14: Remarks
B15: July | C15: 46030 | D15: AV Fistula 16g | E15: 1000 | F15: 52 | G15: 52000 | H15: 52000 | L15: 46030 | M15: 52000
G16: Total | H16: =G15 -> 52000

Sheet SG Pharma Shamoly
A5: Party Name | B5: Month | C5: Sales Date | D5: Item | E5: Qty | F5: Unit Price | G5: Total Price | H5: Paid Amount | I5: Dues Amount | J5: Discount | K5: Total Amount After Discount | L5: Collection Date | M5: Collection Amount | N5: Remarks
A6: SG Pharma Shamoly | B6: May | C6: 14/5/2026 | D6: Dialyzer 1.6H | E6: 30 | F6: 690 | G6: 20700 | H6: 20700 | I6: 0 | K6: =IF(J6>0,G6-J6,"") | L6: 14/5/2026 | M6: 20700 | N6: Forward to MD
F7: Total | G7: =SUM(G6:G6)-SUM(J6:J6) -> 20700 | H7: =H6 -> 20700 | I7: =I6 -> 0 | J7: =SUM(J6:J6) -> 0 | K7: =G7 -> 20700 | L7: Total | M7: =SUM(M6) -> 20700

Sheet Onima Medical
D5: Party Name
B7: Party Name | C7: Month | D7: Sales Date | E7: Item | F7: Qty | G7: Unit Price | H7: Total Price | I7: Paid Amount | J7: Dues Amount | K7: Discount | L7: Total Amount After Discount | M7: Collection Date | N7: Collection Amount | O7: Remarks
B8: Onima Medical | C8: May | D8: 18/5/2026 | E8: Blood Line Sets | F8: 30 | G8: 220 | H8: 6600 | I8: 6600 | J8: 0 | L8: =IF(K8>0,H8-K8,"") | M8: 18/5/2026 | N8: 6600 | O8: 23.05.2026 for Salary May 2026
G9: Total | H9: =SUM(H8:H8)-SUM(K8:K8) -> 6600 | I9: =I8 -> 6600 | J9: =J8 -> 0 | K9: =SUM(K8:K8) -> 0 | L9: =H9 -> 6600 | M9: Total | N9: =SUM(N8) -> 6600

Sheet Rahman Pharma
C4: Party Name | D4: Month | E4: Sales Date | F4: Item | G4: Qty | H4: Unit Price | I4: Total Price | J4: Paid Amount | K4: Dues Amount | L4: Discount | M4: Total Amount After Discount | N4: Collection Date | O4: Collection Amount | P4: Remarks
C5: Rahman Pharma | D5: May | E5: 18/5/2026 | F5: Blood Line Sets | G5: 30 | H5: 225 | I5: 6750 | J5: 6750 | K5: 0 | M5: =IF(L5>0,I5-L5,"") | N5: 19/5/2026 | O5: 10000 | P5: Forward to MD
K6: 0 | N6: 46209 | O6: 7600 | P6: Cash Received by Mostofa
F7: Dialyzer 1.6H | G7: 30 | H7: 695 | I7: =PRODUCT(G7:H7) -> 20850 | J7: 20850 | K7: 0 | M7: =IF(L7>0,I7-L7,"") | N7: 46148 | O7: 10000 | P7: Cash Received by Mr. Saifullah(As Advance Salary)
H8: Total | I8: =SUM(I5:I7)-SUM(L5:L7) -> 27600 | K8: 0 | M8: =I8 -> 27600 | O8: =SUM(O5:O7) -> 27600

Sheet Norshingdi Pharma
A5: Party Name | B5: Month | C5: Sales Date | D5: Item | E5: Qty | F5: Unit Price | G5: Total Price | H5: Paid Amount | I5: Dues Amount | J5: Discount | K5: Total Amount After Discount | L5: Collection Date | M5: Collection Amount | N5: Remarks
A6: Norshingdi Pharma | B6: May | C6: 23/5/2026 | D6: Dialyzer 1.6H | E6: 30 | F6: 680 | G6: 20400 | H6: 20400 | I6: 0 | K6: =IF(J6>0,G6-J6,"") | L6: 24/5/2026 | M6: 20400
F7: Total | G7: =SUM(G6:G6)-SUM(J6:J6) -> 20400 | H7: =H6 -> 20400 | I7: =I6 -> 0 | J7: =SUM(J6:J6) -> 0 | K7: =G7 -> 20400
B9: Month | C9: Sales Date | D9: Item | E9: Qty | F9: Unit Price | G9: Total Price | H9: Paid Amount | I9: Dues Amount | J9: Discount | K9: Total Amount After Discount | L9: Collection Date | M9: Collection Amount | N9: Remarks
B10: June | C10: 46118 | D10: Dialyzer 1.6H | E10: 30 | F10: 680 | G10: 20400 | H10: 20400 | I10: 0 | K10: =IF(J10>0,G10-J10,"") | L10: 46240 | M10: 20400
F11: Total | G11: =SUM(G10)-SUM(J10) -> 20400 | H11: =H10 -> 20400 | I11: =I10 -> 0 | J11: =SUM(J8:J10) -> 0 | K11: =G11 -> 20400
B13: Month | C13: Sales Date | D13: Item | E13: Qty | F13: Unit Price | G13: Total Price | H13: Paid Amount | I13: Dues Amount | J13: Discount | K13: Total Amount After Discount | L13: Collection Date | M13: Collection Amount | N13: Remarks
B14: July | C14: 46149 | D14: Dialyzer 1.5H | E14: 30 | F14: 690 | G14: 20700 | H14: 20700 | I14: 0 | K14: =IF(J14>0,G14-J14,"") | L14: 46149 | M14: 27300
D15: Blood Line Setzs | E15: 30 | F15: 220 | G15: 6600 | H15: 6600 | I15: 0 | K15: =IF(J15>0,G15-J15,"")
F16: Total | G16: =SUM(G14:G15)-SUM(J14:J15) -> 27300 | H16: =SUM(H14:H15) -> 27300 | I16: =SUM(I14:I15) -> 0 | J16: =SUM(J12:J15) -> 0 | K16: =G16 -> 27300 | L16: Total | M16: =SUM(M14) -> 27300

Sheet MA Pharmacy
C5: Party Name | D5: Month | E5: Sales Date | F5: Item | G5: Qty | H5: Unit Price | I5: Total Price | J5: Paid Amount | K5: Dues Amount | L5: Discount | M5: Total Amount After Discount | N5: Collection Date | O5: Collection Amount | P5: Remarks
C6: MA Pharmacy Medical | D6: May | E6: 24/5/2026 | I6: 97500 | J6: 97500 | K6: =IF(AND(I6="",J6=""),"",I6-J6) -> 0 | M6: =IF(L6>0,I6-L6,"") | N6: 24/5/2026 | O6: 97500 | P6: Cash Forward to Office
H7: Total | I7: =SUM(I6:I6)-SUM(L6:L6) -> 97500 | J7: =J6 -> 97500 | K7: =IF(AND(I7="",J7=""),"",I7-J7) -> 0 | L7: =SUM(L6:L6) -> 0 | M7: =I7 -> 97500 | N7: Total | O7: =SUM(O6) -> 97500

Sheet Life Surgical
A6: Party Name | B6: Month | C6: Sales Date | D6: Item | E6: Qty | F6: Unit Price | G6: Total Price | H6: Paid Amount | I6: Dues Amount | J6: Discount | K6: Total Amount After Discount | L6: Collection Date | M6: Collection Amount | N6: Remarks
A7: Life Surgical | B7: May | C7: 16/5/2026 | D7: Dialyzer 1.6H | E7: 30 | F7: 680 | G7: 20900 | H7: 20900 | I7: 0 | K7: =IF(J7>0,G7-J7,"") | L7: 16/5/2026 | M7: 20400 | N7: Deposited to CITYBANK
F8: Total | G8: =SUM(G7:G7)-SUM(J7:J7) -> 20900 | H8: =H7 -> 20900 | I8: =I7 -> 0 | J8: =SUM(J7:J7) -> 0 | K8: =G8 -> 20900
B10: Month | C10: Sales Date | D10: Item | E10: Qty | F10: Unit Price | G10: Total Price | H10: Paid Amount | I10: Dues Amount | J10: Discount | K10: Total Amount After Discount | L10: Collection Date | M10: Collection Amount | N10: Remarks
B11: June | C11: 13/6/2026 | D11: Dialyzer 1.6L | E11: 30 | F11: 680 | G11: 20400 | H11: 20400 | I11: 0 | K11: =IF(J11>0,G11-J11,"") | L11: 14/6/2026 | M11: 20400 | N11: Forward to Office Cash
F12: Total | G12: =SUM(G9:G11)-SUM(J9:J11) -> 20400 | H12: =H11 -> 20400 | I12: =I11 -> 0 | J12: =SUM(J9:J11) -> 0 | K12: =G12 -> 20400

Sheet Chittagong Healthcare
C5: Party Name
A7: Party Name | B7: Month | C7: Sales Date | D7: Item | E7: Qty | F7: Unit Price | G7: Total Price | H7: Paid Amount | I7: Dues Amount | J7: Discount | K7: Total Amount After Discount | L7: Collection Date | M7: Collection Amount | N7: Remarks
A8: Chittagong Healthcare | B8: May | C8: 22/5/2026 | D8: Blood Tubing Set for Hemodialysis | E8: 510 | F8: 220 | G8: 112200 | H8: 112200 | I8: 0 | K8: =IF(J8>0,G8-J8,"") | L8: 21/5/2026 | M8: 500000
D9: Dialyzer for Hemodialysis 1.7H | E9: 150 | F9: 700 | G9: 105000 | H9: 105000 | I9: 0 | K9: =IF(J9>0,G9-J9,"")
D10: Dialyzer for Hemodialysis 1.7L | E10: 150 | F10: 700 | G10: 105000 | H10: 105000 | I10: 0 | K10: =IF(J10>0,G10-J10,"")
D11: Central Vanous Cather 7Fr-13cm | E11: 40 | F11: 1200 | G11: 48000 | H11: 48000 | I11: 0 | K11: =IF(J11>0,G11-J11,"")
D12: Hemodialysis Cather 12Fr-20cm | E12: 40 | F12: 1400 | G12: 56000 | H12: 56000 | I12: 0 | K12: =IF(J12>0,G12-J12,"")
D13: AV Fistula Needle for Hemodialysis | E13: 500 | F13: 55 | G13: 27500 | H13: 27500 | I13: 0 | K13: =IF(J13>0,G13-J13,"")
F14: Total | G14: =SUM(G8:G13)-SUM(J8:J13) -> 453700 | H14: =SUM(H8:H13) -> 453700 | I14: =SUM(I8:I13) -> 0 | J14: =SUM(J8:J13) -> 0 | K14: =G14 -> 453700

Sheet Happy Life Pharmacy
B5: Party Name | C5: Month | D5: Sales Date | E5: Item | F5: Qty | G5: Unit Price | H5: Total Price | I5: Paid Amount | J5: Dues Amount | K5: Discount | L5: Total Amount After Discount | M5: Collection Date | N5: Collection Amount | O5: Remarks
B6: Happy Life Pharmacy | C6: May | D6: 46361 | E6: Dialyzer 1.5H | F6: 30 | G6: 690 | H6: 21000 | I6: 20700 | J6: 0 | L6: =IF(K6>0,H6-K6,"") | M6: 13/5/2026 | N6: 7500 | O6: Forward to MD
E7: Blood Line Sets | F7: 30 | G7: 230 | H7: 6900 | I7: 6900 | J7: 0 | L7: =IF(K7>0,H7-K7,"") | M7: 23/5/2026 | N7: 10000 | O7: Forward to MD
M8: 25/5/2026 | N8: 10000 | O8: Forward to CEO
G9: Total | H9: =SUM(H6:H8)-SUM(K6:K8) -> 27900 | L9: =H9 -> 27900 | M9: Total | N9: =SUM(N6:N8) -> 27500
C12: Month | D12: Sales Date | E12: Item | F12: Qty | G12: Unit Price | H12: Total Price | I12: Paid Amount | J12: Dues Amount | K12: Discount | L12: Total Amount After Discount | M12: Collection Date | N12: Collection Amount | O12: Remarks
C13: June | D13: 46087 | E13: Dialyzer 1.5H | F13: 30 | G13: 700 | H13: 21000 | I13: 21000 | J13: 0 | L13: =IF(K13>0,H13-K13,"") | M13: 14/6/2026 | N13: 15000 | O13: Forward to Merchantile Bank
E14: Blood Line Sets | F14: 30 | G14: 230 | H14: 6900 | I14: 6900 | J14: 0 | L14: =IF(K14>0,H14-K14,"") | M14: 23/6/2026 | N14: 5000 | O14: Cash Forward to MD Sir
M15: 46087 | N15: 15000
G16: Total | H16: =SUM(H13:H14)-SUM(K13:K14) -> 27900 | I16: =SUM(I13:I15) -> 27900 | J16: 0 | K16: =SUM(K13:K14) -> 0 | L16: =H16 -> 27900

Sheet Royal Medical
A4: Party Name | B4: Month | C4: Sales Date | D4: Item | E4: Qty | F4: Unit Price | G4: Total Price | H4: Paid Amount | I4: Dues Amount | J4: Discount | K4: Total Amount After Discount | L4: Collection Date | M4: Collection Amount | N4: Remarks
A5: Royal Medical | B5: June | C5: 46179 | D5: Dialyzer 1.5L | E5: 30 | F5: 680 | G5: 20400 | H5: 20400 | I5: 0 | K5: =IF(J5>0,G5-J5,"") | L5: 46179 | M5: 20400 | N5: Cut from saifullah salary
F6: Total | G6: =SUM(G5:G5)-SUM(J5:J5) -> 20400 | H6: =H5 -> 20400 | I6: =I5 -> 0 | J6: =SUM(J5:J5) -> 0 | K6: =G6 -> 20400

Sheet USB Hospital Uttara
B4: Party Name | C4: Month | D4: Sales Date | E4: Item | F4: Qty | G4: Unit Price | H4: Total Price | I4: Paid Amount | J4: Dues Amount | K4: Discount | L4: Total Amount After Discount | M4: Collection Date | N4: Collection Amount | O4: Remarks
B5: USB Hospital Uttara | C5: June | D5: 46029 | E5: Catheter/C.V. Line | F5: 10 | G5: 1200 | H5: 12000 | I5: 12000 | M5: 46029 | N5: 6000 | O5: Forward to cash
J6: 0 | L6: =IF(K6>0,H6-K6,"") | M6: 46060 | N6: 6000 | O6: Forward to cash
G7: Total | H7: =SUM(H5:H6)-SUM(K5:K6) -> 12000 | I7: =SUM(I5:I6) -> 12000 | J7: =SUM(J6:J6) -> 0 | K7: =SUM(K6:K6) -> 0 | L7: =H7 -> 12000 | M7: Total | N7: =SUM(N5:N6) -> 12000

Sheet Asha International
B4: Party Name | C4: Month | D4: Sales Date | E4: Item | F4: Qty | G4: Unit Price | H4: Total Price | I4: Paid Amount | J4: Dues Amount | K4: Discount | L4: Total Amount After Discount | M4: Collection Date | N4: Collection Amount | O4: Remarks
B5: Asha International | C5: June | D5: 29/6/26 | E5: Blood Line Sets | F5: 740 | G5: 500 | H5: 370000 | I5: 275000 | J5: =IF(AND(H5="",I5=""),"",H5-I5) -> 95000 | L5: =IF(K5>0,H5-K5,"") | M5: 29/6/2026 | N5: 400000 | O5: Forward to Merchantile Bank
E6: Catheter | F6: 250 | G6: 500 | H6: 125000 | I6: 125000 | J6: 0 | L6: =IF(K6>0,H6-K6,"")
G7: Total | H7: =SUM(H5:H6)-SUM(K5:K6) -> 495000 | I7: =SUM(I5:I6) -> 400000 | J7: =SUM(J5:J6) -> 95000 | K7: =SUM(K5:K6) -> 0 | L7: =H7 -> 495000

Sheet Star Surgical
B5: Party Name | C5: Month | D5: Sales Date | E5: Item | F5: Qty | G5: Unit Price | H5: Total Price | I5: Paid Amount | J5: Dues Amount | K5: Discount | L5: Total Amount After Discount | M5: Collection Date | N5: Collection Amount | O5: Remarks
B6: Star Surgical | C6: July | D6: 46149 | E6: Blood Line Sets | F6: 60 | G6: 230 | H6: 13800 | I6: 13800 | J6: =IF(AND(H6="",I6=""),"", H6-I6) -> 0 | L6: =IF(K6>0,H6-K6,"") | M6: 46210 | N6: 6000 | O6: Forward to Cash
E7: Dialyzer 1.5H | F7: 30 | G7: 720 | H7: 21600 | I7: 21600 | J7: =IF(AND(H7="",I7=""),"", H7-I7) -> 0 | L7: =IF(K7>0,H7-K7,"") | M7: 23/7/2026 | N7: 16500
D8: 23/7/2026 | E8: Blood Line Sets | F8: 150 | G8: 220 | H8: 33000 | I8: 10000 | J8: =IF(AND(H8="",I8=""),"", H8-I8) -> 23000 | M8: 46061 | N8: 10000
G9: Total | H9: =SUM(H6:H8)-SUM(K6:K8) -> 68400 | I9: =SUM(I6:I8) -> 45400 | J9: =SUM(J6:J8) -> 23000 | K9: =SUM(K6:K7) -> 0 | L9: =H9 -> 68400 | N9: =SUM(N6:N8) -> 32500

Sheet Sylhet Pharma
B5: Party Name | C5: Month | D5: Sales Date | E5: Item | F5: Qty | G5: Unit Price | H5: Total Price | I5: Paid Amount | J5: Dues Amount | K5: Discount | L5: Total Amount After Discount | M5: Collection Date | N5: Collection Amount | O5: Remarks
B6: Sylhet Pharma | C6: July | D6: 46149 | E6: Blood Line Sets | F6: 60 | G6: 225 | H6: 13500 | J6: 13500
E7: Dialyzer 1.5H | F7: 6 | G7: 720 | H7: 4320 | I7: 0 | J7: 4320 | L7: =IF(K7>0,H7-K7,"")
G8: Total | H8: =SUM(H6:H7)-SUM(K6:K7) -> 17820 | I8: =I7 -> 0 | J8: =SUM(J6:J7) -> 17820 | K8: =SUM(K7:K7) -> 0 | L8: =H8 -> 17820

Sheet Bulbul Surgical
C5: Party Name | D5: Month | E5: Sales Date | F5: Item | G5: Qty | H5: Unit Price | I5: Total Price | J5: Paid Amount | K5: Dues Amount | L5: Discount | M5: Total Amount After Discount | N5: Collection Date | O5: Collection Amount | P5: Remarks
C6: Bulbul Surgical | D6: July | E6: 46149 | F6: Blood Line Sets | G6: 60 | H6: 225 | I6: 13500 | J6: 0 | K6: 0 | L6: =IF(AND(I6="",J6=""), "", I6-J6) -> 13500 | M6: =IF(L6>0,I6-L6,"") -> 0 | N6: 46210 | O6: 13500
H7: Total | I7: =SUM(I6:I6)-SUM(L6:L6) -> 0 | J7: 0 | K7: 0 | L7: =SUM(L6:L6) -> 13500 | M7: =I7 -> 0

Sheet Suzon Pharma (Rang)
C7: Party Name | D7: Month | E7: Sales Date | F7: Item | G7: Qty | H7: Unit Price | I7: Total Price | J7: Paid Amount | K7: Dues Amount | L7: Discount | M7: Total Amount After Discount | N7: Collection Date | O7: Collection Amount | P7: Remarks
C8: Suzon Pharma (Rangpur) | D8: July | E8: 46241 | F8: Dialyzer 1.5H | G8: 30 | H8: 700 | I8: 21000 | J8: 21000 | K8: 0 | M8: =IF(L8>0,I8-L8,"") | N8: 46363 | O8: 20800 | P8: Cash Forward to CEO
E9: 27/7/2026 | F9: Dialyzer 1.5L | G9: 30 | H9: 700 | I9: 21000 | J9: 21000 | K9: 0 | L9: 0 | N9: 29/7/2026 | O9: 20800
H10: Total | I10: =SUM(I8:I9)-SUM(L8:L9) -> 42000 | J10: =SUM(J8:J9) -> 42000 | K10: =IF(AND(I10="",J10=""), "", I10-J10) -> 0 | L10: =SUM(L8:L8) -> 0 | M10: =I10 -> 42000 | O10: =SUM(O8:O9) -> 41600

Sheet SH Pharma
B3: Party Name | C3: Month | D3: Sales Date | E3: Item | F3: Qty | G3: Unit Price | H3: Total Price | I3: Paid Amount | J3: Dues Amount | K3: Discount | L3: Total Amount After Discount | M3: Collection Date | N3: Collection Amount | O3: Remarks
B4: SH Pharma | C4: July | D4: 46363 | E4: Blood Line Sets | F4: 150 | G4: 200 | H4: 30000 | I4: 30000 | J4: 0 | L4: =IF(K4>0,H4-K4,"") | M4: 46363 | N4: 30000
D5: 25/7/2026 | E5: Blood Line Sets | F5: 300 | G5: 200 | H5: 63000 | I5: 30000 | J5: =IF(AND(H5="", I5=""), "", H5-I5) -> 33000 | L5: =IF(K5>0,H5-K5,"") | M5: 46030 | N5: 30000
G8: Total | H8: =SUM(H4:H6)-SUM(K4:K6) -> 93000 | I8: =SUM(I4:I6) -> 60000 | J8: =SUM(J4:J6) -> 33000 | K8: =SUM(K4:K6) -> 0 | L8: =H8 -> 93000 | M8: Total | N8: =SUM(N4:N7) -> 60000
C12: Month | D12: Sales Date | E12: Item | F12: Qty | G12: Unit Price | H12: Total Price | I12: Paid Amount | J12: Dues Amount | K12: Discount | L12: Total Amount After Discount | M12: Collection Date | N12: Collection Amount | O12: Remarks
C13: August | D13: 46089 | E13: Blood Line Sets | F13: 150 | G13: 210 | H13: 31500 | I13: 30000 | J13: 1500 | K13: 0 | M13: 46181 | N13: 31500 | O13: 1500 commision saifullah
G15: Total | H15: =SUM(H13)-SUM(K13) -> 31500 | I15: =SUM(I13:I14) -> 30000 | J15: =SUM(J13:J14) -> 1500 | M15: Total | N15: =SUM(N13:N14) -> 31500

Sheet Mymen. Sayem Diagnostic Center
E3: Party Name
B5: Party Name | C5: Month | D5: Sales Date | E5: Item | F5: Qty | G5: Unit Price | H5: Total Price | I5: Paid Amount | J5: Dues Amount | K5: Discount | L5: Total Amount After Discount | M5: Collection Date | N5: Collection Amount | O5: Remarks
B6: Mymen. Sayem Diagnostic Center | C6: July | D6: 46180 | E6: AV Fistula 16g | F6: 250 | G6: 60 | H6: 15000 | I6: 15000 | J6: 0 | L6: =IF(K6>0,H6-K6,"") | M6: 46363 | N6: 15000 | O6: Cash forward to Mercantile Bank
G7: Total | H7: =SUM(H6:H6)-SUM(K6:K6) -> 15000 | I7: =I6 -> 15000 | J7: 0 | K7: =SUM(K6:K6) -> 0 | L7: =H7 -> 15000 | M7: Total | N7: =SUM(N6) -> 15000

Sheet Mitfort Hospital
E4: Party Name | F4: Mitfort Hospital
E5: June
E6: Sales Date | F6: Item | G6: Qty | H6: Unit Price | I6: 7.5% VAT | J6: 7% AIT | K6: Total Price without VAT and AIT | L6: Total Price with VAT and AIT | M6: Paid Amount | N6: Dues Amount | O6: Discount | P6: Total Amount After Discount | Q6: Collection Date | R6: Collection Amount | S6: Remarks
E7: 46209 | F7: Dialyzer 1.8H | G7: 150 | H7: 620 | I7: =H7*7.5% -> 46.5 | J7: =H7*7% -> 43.4 | K7: =G7*H7 -> 93000 | L7: =G7*SUM(H7:J7) -> 106485 | N7: 0 | P7: =IF(O7>0,L7-O7,"")
F8: Dialyzer 1.7H | G8: 538 | H8: 620 | I8: =H8*7.5% -> 46.5 | J8: =H8*7% -> 43.4 | K8: =G8*H8 -> 333560 | L8: =G8*SUM(H8:J8) -> 381926.2 | N8: 0 | P8: =IF(O8>0,L8-O8,"")
E9: 46240 | F9: Dialyzer 1.7H | G9: 598 | H9: 620 | I9: =H9*7.5% -> 46.5 | J9: =H9*7% -> 43.4 | K9: =G9*H9 -> 370760 | L9: =G9*SUM(H9:J9) -> 424520.2 | N9: 0 | P9: =IF(O9>0,L9-O9,"") | Q9: 46240 | R9: 500000
E10: 46332 | F10: Dialyzer 1.7L | G10: 570 | H10: 620 | I10: =H10*7.5% -> 46.5 | J10: =H10*7% -> 43.4 | K10: =G10*H10 -> 353400 | L10: =G10*SUM(H10:J10) -> 404643 | N10: 0 | P10: =IF(O10>0,L10-O10,"")
F11: Dialyzer 1.6L | G11: 30 | H11: 620 | I11: =H12*7.5% -> 46.5 | J11: =H12*7% -> 43.4 | K11: =G11*H12 -> 18600 | L11: =G11*SUM(H11:J11) -> 21297 | N11: 0 | P11: =IF(O11>0,L11-O11,"")
E12: 13/6/2026 | F12: Dialyzer 1.5H | G12: 360 | H12: 620 | I12: =H13*7.5% -> 46.5 | J12: =H13*7% -> 43.4 | K12: =G12*H13 -> 223200 | L12: =G12*SUM(H12:J12) -> 255564
F13: Dialyzer 1.5L | G13: 180 | H13: 620 | I13: =H14*7.5% -> 46.5 | J13: =H14*7% -> 43.4 | K13: =G13*H14 -> 111600 | L13: =G13*SUM(H13:J13) -> 127782
F14: Dialyzer 1.6H | G14: 120 | H14: 620 | I14: =H14*7.5% -> 46.5 | J14: =H14*7% -> 43.4 | K14: =G14*H14 -> 74400 | L14: =G14*SUM(H14:J14) -> 85188 | N14: 0 | P14: =IF(O14>0,L14-O14,"")
F15: Dialyzer 1.8H | G15: 90 | H15: 620 | I15: =H15*7.5% -> 46.5 | J15: =H15*7% -> 43.4 | K15: =G15*H15 -> 55800 | L15: =G15*SUM(H15:J15) -> 63891
E16: 17/6/2026 | F16: Dialyzer | G16: 210 | H16: 620 | I16: =H16*7.5% -> 46.5 | J16: =H16*7% -> 43.4 | K16: =G16*H16 -> 130200 | L16: =G16*SUM(H16:J16) -> 149079 | N16: 0 | P16: =IF(O16>0,L16-O16,"")
G17: =SUM(G7:G16) -> 2846 | J17: Total | K17: =SUM(K7:K16) -> 1764520 | M17: 500000 | N17: =K17-M17 -> 1264520 | O17: =SUM(O7:O16) -> 0 | P17: =L17 -> 0

Sheet Sonu Pharma
B3: Party Name | C3: Month | D3: Sales Date | E3: Item | F3: Qty | G3: Unit Price | H3: Total Price | I3: Paid Amount | J3: Dues Amount | K3: Discount | L3: Total Amount After Discount | M3: Collection Date | N3: Collection Amount | O3: Remarks
B4: Sonu Pharma | C4: August | D4: 46089 | E4: Blood Line Sets | F4: 150 | G4: 210 | H4: 31500 | I4: 0
E5: Total | F5: 31500 | J5: 31500

Sheet Insaf Baraka Foundation
B5: Party Name | C5: Month | D5: Sales Date | E5: Item | F5: Qty | G5: Unit Price | H5: Total Price | I5: Paid Amount | J5: Dues Amount | K5: Discount | L5: Total Amount After Discount | M5: Collection Date | N5: Collection Amount | O5: Remarks
B6: Insaf Baraka Foundation | C6: August | D6: 46120 | E6: Blood Line Sets | F6: 60 | G6: 210 | H6: 12600 | I6: 0 | J6: 12600 | K6: 0
G7: Total | H7: 12600 | J7: 12600 | L7: 12600

Sheet Data
A1: Source Sheet | B1: Month | C1: Item (raw) | D1: Qty | E1: Unit Price | F1: Item Code
A2: ARK Hospital | B2: April | C2: ='ARK Hospital'!D5 -> Dialyzer 1.7H | D2: ='ARK Hospital'!E5 -> 60 | E2: ='ARK Hospital'!F5 -> 680 | F2: =IFERROR(INDEX('Item Mapping'!$B$2:$B$31,MATCH(C2,'Item Mapping'!$A$2:$A$31,0)),"UNMAPPED") -> ITEM01
A3: ARK Hospital | B3: April | C3: ='ARK Hospital'!D6 -> Blood Line Sets | D3: ='ARK Hospital'!E6 -> 30 | E3: ='ARK Hospital'!F6 -> 230 | F3: =IFERROR(INDEX('Item Mapping'!$B$2:$B$31,MATCH(C3,'Item Mapping'!$A$2:$A$31,0)),"UNMAPPED") -> ITEM10
A4: ARK Hospital | B4: April | C4: ='ARK Hospital'!D7 -> Central Vanous Cather 7Fr-13cm | D4: ='ARK Hospital'!E7 -> 10 | E4: ='ARK Hospital'!F7 -> 1300 | F4: =IFERROR(INDEX('Item Mapping'!$B$2:$B$31,MATCH(C4,'Item Mapping'!$A$2:$A$31,0)),"UNMAPPED") -> ITEM13
A5: ARK Hospital | B5: May | C5: ='ARK Hospital'!D11 -> Dialyzer 1.7H | D5: ='ARK Hospital'!E11 -> 90 | E5: ='ARK Hospital'!F11 -> 680 | F5: =IFERROR(INDEX('Item Mapping'!$B$2:$B$31,MATCH(C5,'Item Mapping'!$A$2:$A$31,0)),"UNMAPPED") -> ITEM01
A6: ARK Hospital | B6: May | C6: ='ARK Hospital'!D12 -> Blood Line Sets | D6: ='ARK Hospital'!E12 -> 30 | E6: ='ARK Hospital'!F12 -> 230 | F6: =IFERROR(INDEX('Item Mapping'!$B$2:$B$31,MATCH(C6,'Item Mapping'!$A$2:$A$31,0)),"UNMAPPED") -> ITEM10
A7: ARK Hospital | B7: May | C7: ='ARK Hospital'!D13 -> Dialyzer 1.7H | D7: ='ARK Hospital'!E13 -> 60 | E7: ='ARK Hospital'!F13 -> 680 | F7: =IFERROR(INDEX('Item Mapping'!$B$2:$B$31,MATCH(C7,'Item Mapping'!$A$2:$A$31,0)),"UNMAPPED") -> ITEM01
A8: ARK Hospital | B8: May | C8: ='ARK Hospital'!D14 -> Blood Line Sets | D8: ='ARK Hospital'!E14 -> 30 | E8: ='ARK Hospital'!F14 -> 230 | F8: =IFERROR(INDEX('Item Mapping'!$B$2:$B$31,MATCH(C8,'Item Mapping'!$A$2:$A$31,0)),"UNMAPPED") -> ITEM10
A9: ARK Hospital | B9: May | C9: ='ARK Hospital'!D15 -> Dialyzer 1.7H | D9: ='ARK Hospital'!E15 -> 30 | E9: ='ARK Hospital'!F15 -> 680 | F9: =IFERROR(INDEX('Item Mapping'!$B$2:$B$31,MATCH(C9,'Item Mapping'!$A$2:$A$31,0)),"UNMAPPED") -> ITEM01
A10: ARK Hospital | B10: May | C10: ='ARK Hospital'!D16 -> Dialyzer 1.7L | D10: ='ARK Hospital'!E16 -> 30 | E10: ='ARK Hospital'!F16 -> 680 | F10: =IFERROR(INDEX('Item Mapping'!$B$2:$B$31,MATCH(C10,'Item Mapping'!$A$2:$A$31,0)),"UNMAPPED") -> ITEM02
A11: ARK Hospital | B11: May | C11: ='ARK Hospital'!D17 -> Blood Line Sets | D11: ='ARK Hospital'!E17 -> 30 | E11: ='ARK Hospital'!F17 -> 230 | F11: =IFERROR(INDEX('Item Mapping'!$B$2:$B$31,MATCH(C11,'Item Mapping'!$A$2:$A$31,0)),"UNMAPPED") -> ITEM10
A12: ARK Hospital | B12: June | C12: ='ARK Hospital'!D21 -> Dialyzer 1.5H | D12: ='ARK Hospital'!E21 -> 60 | E12: ='ARK Hospital'!F21 -> 680 | F12: =IFERROR(INDEX('Item Mapping'!$B$2:$B$31,MATCH(C12,'Item Mapping'!$A$2:$A$31,0)),"UNMAPPED") -> ITEM03
A13: ARK Hospital | B13: June | C13: ='ARK Hospital'!D22 -> Dialyzer 2.0 | D13: ='ARK Hospital'!E22 -> 30 | E13: ='ARK Hospital'!F22 -> 680 | F13: =IFERROR(INDEX('Item Mapping'!$B$2:$B$31,MATCH(C13,'Item Mapping'!$A$2:$A$31,0)),"UNMAPPED") -> ITEM08
A14: ARK Hospital | B14: June | C14: ='ARK Hospital'!D23 -> Dialyzer 1.5H | D14: ='ARK Hospital'!E23 -> 60 | E14: ='ARK Hospital'!F23 -> 680 | F14: =IFERROR(INDEX('Item Mapping'!$B$2:$B$31,MATCH(C14,'Item Mapping'!$A$2:$A$31,0)),"UNMAPPED") -> ITEM03
A15: ARK Hospital | B15: June | C15: ='ARK Hospital'!D24 -> Dialyzer 1.5H | D15: ='ARK Hospital'!E24 -> 60 | E15: ='ARK Hospital'!F24 -> 680 | F15: =IFERROR(INDEX('Item Mapping'!$B$2:$B$31,MATCH(C15,'Item Mapping'!$A$2:$A$31,0)),"UNMAPPED") -> ITEM03
A16: Bismillah Surgical | B16: April | C16: ='Bismillah Surgical'!D4 -> Dialyzer 1.5H | D16: ='Bismillah Surgical'!E4 -> 30 | E16: ='Bismillah Surgical'!F4 -> 700 | F16: =IFERROR(INDEX('Item Mapping'!$B$2:$B$31,MATCH(C16,'Item Mapping'!$A$2:$A$31,0)),"UNMAPPED") -> ITEM03
A17: Bismillah Surgical | B17: April | C17: ='Bismillah Surgical'!D5 -> Dialyzer 1.5L | D17: ='Bismillah Surgical'!E5 -> 30 | E17: ='Bismillah Surgical'!F5 -> 700 | F17: =IFERROR(INDEX('Item Mapping'!$B$2:$B$31,MATCH(C17,'Item Mapping'!$A$2:$A$31,0)),"UNMAPPED") -> ITEM04
